Workbook

Sheet Overview
A2: Pulse table 整理與測站座標
A4: 目前有效記錄表 | B4: 來源記錄數 | C4: 原表已有座標 | D4: 本次比對補齊 | E4: 座標有歧義 | F4: 尚未找到 | G4: 座標涵蓋率
A5: S&B | B5: =COUNTIF(Pulse_records!$CK$2:$CK$702,A5) -> 243 | C5: =COUNTIFS(Pulse_records!$CK$2:$CK$702,A5,Pulse_records!$J$2:$J$702,"original") -> 0 | D5: =COUNTIFS(Pulse_records!$CK$2:$CK$702,A5,Pulse_records!$J$2:$J$702,"matched") -> 241 | E5: =COUNTIFS(Pulse_records!$CK$2:$CK$702,A5,Pulse_records!$J$2:$J$702,"ambiguous") -> 0 | F5: =COUNTIFS(Pulse_records!$CK$2:$CK$702,A5,Pulse_records!$J$2:$J$702,"unresolved") -> 2 | G5: =(C5+D5)/B5 -> 0.99176955
A6: NCREE | B6: =COUNTIF(Pulse_records!$CK$2:$CK$702,A6) -> 340 | C6: =COUNTIFS(Pulse_records!$CK$2:$CK$702,A6,Pulse_records!$J$2:$J$702,"original") -> 340 | D6: =COUNTIFS(Pulse_records!$CK$2:$CK$702,A6,Pulse_records!$J$2:$J$702,"matched") -> 0 | E6: =COUNTIFS(Pulse_records!$CK$2:$CK$702,A6,Pulse_records!$J$2:$J$702,"ambiguous") -> 0 | F6: =COUNTIFS(Pulse_records!$CK$2:$CK$702,A6,Pulse_records!$J$2:$J$702,"unresolved") -> 0 | G6: =(C6+D6)/B6 -> 1
A7: YEN | B7: =COUNTIF(Pulse_records!$CK$2:$CK$702,A7) -> 118 | C7: =COUNTIFS(Pulse_records!$CK$2:$CK$702,A7,Pulse_records!$J$2:$J$702,"original") -> 0 | D7: =COUNTIFS(Pulse_records!$CK$2:$CK$702,A7,Pulse_records!$J$2:$J$702,"matched") -> 118 | E7: =COUNTIFS(Pulse_records!$CK$2:$CK$702,A7,Pulse_records!$J$2:$J$702,"ambiguous") -> 0 | F7: =COUNTIFS(Pulse_records!$CK$2:$CK$702,A7,Pulse_records!$J$2:$J$702,"unresolved") -> 0 | G7: =(C7+D7)/B7 -> 1
G8: =(C8+D8)/B8 -> #DIV/0!
G9: =(C9+D9)/B9 -> #DIV/0!
A10: 總計（含跨來源重複） | B10: =SUM(B5:B7) -> 701 | C10: =SUM(C5:C7) -> 340 | D10: =SUM(D5:D7) -> 359 | E10: =SUM(E5:E7) -> 0 | F10: =SUM(F5:F7) -> 2 | G10: =(C10+D10)/B10 -> 0.99714693
A13: 主表已統一為 S&B 243 + NCREE 340 + YEN 118 = 701 筆。已排除 275 筆歷史／其他處理版本；跨來源重複仍保留，701 並非獨立樣本數。
A14: Pulse_records 可篩選來源、處理版本、測站與座標狀態。
A15: Tp、Tf、水平／垂直 Tp 及各分量 PGV 分別保存。
A16: 尚缺座標：Port Island (83 m)、SERVICE HALL:50.8 M DEPTH，共2筆；主表699/701有座標。47004已由使用者補上。
A17: 汶川 051* 座標僅至 0.1°。TCU074 有來源位置衝突，請先讀備註。
A18: 目前記錄表：S&B、NCREE、YEN。主表 active_sheet / active_row 指向現有分頁；source_sheet / source_row 保留原始來源。
A19: Kamai 84筆與相關7個 source_error 已不在有效主表範圍；原檔保留作歷史追溯。
A32: Event / finite-fault update | B32: 2026-09-10; latest user workbook retained; source enrichments are a dated snapshot.
A33: Merged records | B33: YEN 118筆已與主表逐列對應；Pazarcik/Elbistan的30筆R_hypo透過公式同步。
A34: Earthquake sources | B34: 75個事件分成111個來源／事件組合：S&B46、NCREE56、YEN9。以event_source_key連結，不再假設同事件在不同來源使用相同震源。
A35: USGS finite-fault coverage | B35: 9 matched models, 23 fault segments. No matching USGS product does not mean no published finite-fault model exists.
A36: Ilan–Suao event | B36: User confirmed 2005-03-05 19:08 UTC; linked to USGS usp000dhkp.
A37: Missing source angles | B37: 2001 Taipo and 2007 Taitung lack moment-tensor/focal-mechanism products in retrieved USGS detail; angles left blank.
A38: Plane definitions | B38: Table 1的熊本主震列出205°/72°與235°/65°，rake均為−142°；分欄保留，不宣稱為共軛節面。其餘事件的plane_definition標明來源。
A39: Finite-fault units | B39: Lengths, widths and depths: km; slip: m; moment: N m; rise time: s; rupture speed: km/s. Model area sums segment LEN × WID, not slipped area.
A40: Finite-fault slip / rake | B40: Max slip calculated from all FSP subfault SLIP values (m). Segment rake ranges retain FSP angle convention; no single rake imposed on multi-segment models.
A41: Model geometry | B41: Full FSP modeled dimensions are reported, not effective slipped-patch dimensions. Segment lengths are not summed as physical rupture length; negative source top depth is retained.
A42: Source priority | B42: 原來源欄位優先：S&B採NGA；NCREE採原列座標、深度、Mw及fault type；YEN採原Mw與使用者Table1。沒有原欄位時保留既有資料，並由origin_source / mechanism_source / time_source_url區分來源。
A43: Update behavior | B43: 主表依三個現有記錄表整理，active_sheet / active_row為當前位置；30筆新計算R_hypo由YEN公式連動，其他值為本次快照。repeat_count與Station_coords已按701筆重算。
... A47: Finite-fault identity | B47: All 9 assigned finite-fault models have the same USGS event IDs as the audited events. Model-specific magnitudes, hypocenters and rupture planes remain separate.
A50: 資料完整性與一致性檢查 — 2026-09-10
A51: 狀態 | B51: 檢查項目 | D51: 結果、位置與建議
A52: 已同步 | B52: 30 筆 R_hypo 已同步 | D52: YEN!F90:F119 的30筆計算值已由公式連到Pulse_records。因主表縮編，YEN公式中的測站座標列號已重新對應；保留原計算值與來源方法。
A53: 需確認 | B53: 已按原來源重做距離檢查 | D53: 目前YEN有17筆Rhyp待查；Iburi四筆已按使用者指示，以原FSP震源重算並更新。原Rrup皆保留。
A54: 已確認 | B54: KumaFore 前震已確認 | D54: 圖中Table 1明列2016-04-14 12:26:36 UTC、Mw6.1。YEN 12筆前震事件欄位與主表已更新；不再標為provisional。
A55: 已排除 | B55: Kamai 不再屬於主表 | D55: 已移除有效主表中的Kamai 84筆；原有7個Normalized Dsite錯誤不在本次701筆範圍。沒有嘗試修正歷史來源的錯誤。
A56: 缺值 | B56: 2 筆主表測站座標 | D56: Pulse_records第117/213列仍缺座標：Port Island (83m)、SERVICE HALL 50.8m。47004（第668列）已採使用者提供的141.9204E、42.6226N；主表699/701有座標。
A57: 缺值 | B57: Duzce 2022 的 R_rup | D57: YEN!E86:E89，4筆（8101/8102/8104/8109）空白。不能用 R_hypo 或震央距離代替 R_rup；需要相應斷層面模型。
A58: 缺值 | B58: Iburi 斷層平行方位 | D58: YEN!J82:J85，4筆空白（HKD126/HKD128/IBUH01/47004）。需先選定適用的斷層走向與角度定義。
A59: 缺值 | B59: Pardee–SCE 兩種方位 | D59: S&B!J108:K108 為 -999 缺值碼；不是有效角度。同列 Fault Normal Pulse（L108）也為 -999，不能直接作布林值。
A60: 缺值 | B60: NCREE 的 Vs30 | D60: NCREE!J279/J319/J321/J341 為文字 None：Kanti Path、SHH、TRB029、TRB042。需站址資料；未補值。
A61: 缺值 | B61: 2 個事件的斷層角度 | D61: Event_sources 的 2001_taipo、2007_taitung 缺 strike/dip/rake。先前取得的 USGS 事件資料沒有 moment-tensor/focal-mechanism；保留空白，並非誤配的直接證據。
...

Sheet Sources_method
A1: source_id | B1: source | C1: locator | D1: source_note | E1: accessed_or_read
A2: S01 | B2: 使用者原始 pulse table | C2: scaling_2024.xlsx | D2: 原始檔保留不變；每筆記錄有來源工作表與原始列號。 | E2: 2026-09-09
A3: S02 | B3: NGA-West2 更新 flatfile（2015，公開檔鏡像） | C3: https://raw.githubusercontent.com/personlin/NGA-West2_Flatfile/main/data/Updated_NGA_West2_Flatfile_RotD50_d050_public_version.xlsx | D3: PEER 官方下載回傳 403，使用公開原始 XLSX 鏡像；未驗證與官方檔案的雜湊一致性。官方索引：https://peer.berkeley.edu/node/74 | E3: 2026-09-09
A4: S03 | B4: 熊本本地測站清單 | C4: pulse/data/events/2016_Kumamoto/station_list | D4: 無欄名；依數值範圍辨識 station, longitude, latitude；未額外確認座標基準。 | E4: 2026-09-09
A5: S04 | B5: 集集本地測站資訊 | C5: pulse/data/events/1999_ChiChi/1999_station_inf | D5: 欄名明列 sta, lat, lon。 | E5: 2026-09-09
A6: S05 | B6: 土耳其 2023 第一主震 pulse flatfile | C6: pulse/03_scaling/tables/Turkey_202302060117_flatfile_geometric_mean_pulse.csv | E6: 2026-09-09
A7: S06 | B7: 土耳其 2023 第二主震 pulse flatfile | C7: pulse/03_scaling/tables/Turkey_202302061024_flatfile_geometric_mean_pulse.csv | D7: 131、132 保留原代碼，不自行加 TK 網路前綴。 | E7: 2026-09-09
A8: S07 | B8: 土耳其 2023 第一主震完整 flatfile | C8: pulse/data/events/2023_Turkey/Turkey_202302060117_flatfile_geometric_mean.csv | D8: TK-#### 或 KO-代碼去除已列明的網路前綴後比對。 | E8: 2026-09-09
A9: S08 | B9: NIED 歷史測站位置（2022-02-01 前） | C9: https://www.kyoshin.bosai.go.jp/en/stationlocationinfobefore20220201/ | E9: 2026-09-09
A10: S09 | B10: Düzce 2022 研究 Table 2 | C10: https://dergipark.org.tr/en/download/article-file/3476680 | D10: 使用表列四位小數測站經緯度。 | E10: 2026-09-09
A11: S10 | B11: NIED Hi-net 追分測站更新資訊 | C11: https://www.hinet.bosai.go.jp/st_info/st_update/?LANG=ja&r=HFHKS2007&rym=200710 | D11: IBUH01，2007-10 起位置。 | E11: 2026-09-09
A12: S11 | B12: 土耳其測站代碼對照，PEER 研究報告 Table 1 | C12: https://apps.peer.berkeley.edu/lifelines/lifelines_pre_2006/final_reports/2A02a-FR.pdf | D12: IZT=Izmit；SKR=Sakarya；YPT=Yarimca；BOL=Bolu；DZC=Duzce。 | E12: 2026-09-09
A13: S12 | B13: L’Aquila 記錄代碼／測站對照 | C13: https://www.reluis.it/doc/pdf/Aquila/Confronto_L%27Aquila-NTC_V1.pdf | D13: AM043=AQK Parking；CU104=AQA F. Aterno；FA030=AQG Colle Grilli；GX066=AQV Centro Valle。 | E13: 2026-09-09
A16: 項目 | B16: 整理規則與限制
A17: 整理範圍 | B17: 7 個記錄表合併為 976 筆來源記錄。regression 為關係式／曲線資料，保留在原表快照，不併入觀測記錄。
A18: 完整原始資料 | B18: 後方 8 個同名工作表保留原始儲存值快照（含旁欄統計）。原檔未修改；公式、圖表與樣式未複製，快照不作動態試算。
A19: 缺值 | B19: 文字 NaN、None 在整理表改為空白；missing_fields_original 保留原缺值標記。真實 0 與 FALSE 不轉成缺值。
A20: 測站識別 | B20: station_original 保留原名；station_key 以事件推定區域加名稱的英數正規化值建立。比對鍵不是經權威機構核定的全球唯一測站 ID。
A21: Station_coords 粒度 | B21: 每列為測站比對鍵、座標值與狀態的組合。同一測站可因事件、來源或小數精度不同而有多列；不可直接當唯一測站數。
A22: 版本與重複 | B22: 保留 Baker_moderate、Baker(2014)、校正／未校正 fling、NCREE 的全部來源記錄；不可將跨來源記錄直接當獨立樣本。
A23: repeat_group | B23: 有 RSN 時採 NGA:RSN；否則以原事件名稱、年份與測站比對鍵分組。未跨事件別名整併，因此僅為部分重複提示。
A24: Tp 與 Tf | B24: Tp_s、Tf_s、Tp_H_s、Tp_V_s 分欄保存，不互相替代。NCREE 水平及垂直週期不直接併入 Tp_s。
A25: 距離 | B25: Baker Closest Dist. 保留為 closest_distance_km，不自動宣稱為 Rrup。明列 Rrup 的資料才填 Rrup_km。
A26: PGV | B26: PGV_cm_s 為來源 pulse 表的 PGV；NCREE 各分量 PGV_*_original 分開保存，不自行取最大值或合成。
A27: 未明示單位 | B27: *_original 與 Kamai displacement 欄位保留原值；原欄名未明示的單位或機制代碼定義，不自行推定。
... A35: 重新整理 | B35: 本檔為 2026-09-09 整理快照。修改來源表不會自動重新執行座標比對；Overview 計數會隨 Pulse_records 更新。
A37: E01 | B37: USGS finite-fault catalog | C37: https://earthquake.usgs.gov/data/finitefault/ | D37: Archive queried for 1900–2023 producttype=finite-fault; preferred product by preferredWeight then updateTime. Full model FSP geometry and download URLs in Event_sources / Finite_fault_segments. | E37: 2026-09-10
A38: E02 | B38: USGS ComCat event details | C38: https://earthquake.usgs.gov/fdsnws/event/1/ | D38: Matched events reviewed by date, location, magnitude and sequence. Origin uses preferred event geometry/time; moment-tensor product source/version recorded separately. | E38: 2026-09-10
A39: E03 | B39: NGA-West2 updated2015 flatfile official index | C39: https://peer.berkeley.edu/node/74 | D39: 47 event metadata matches by normalized event/year; original NGA row and EQID retained. No -999 sentinel used as a physical value. | E39: 2026-09-10
A40: E04 | B40: NGA flatfile download mirror | C40: https://raw.githubusercontent.com/personlin/NGA-West2_Flatfile/main/data/Updated_NGA_West2_Flatfile_RotD50_d050_public_version.xlsx | D40: Official download unavailable; used this mirror, not independently hash-verified against official distribution. Magnitude type U and NGA finite-fault flags retained as source codes. | E40: 2026-09-10
A41: E05 | B41: Wang et al. 2004 Table1 (Chi-Chi sequence) | C41: https://citeseerx.ist.psu.edu/document?doi=3c7c3853c5d32c9f6a371bf9461e847d08a9099f&repid=rep1&type=pdf | D41: Event alias checks: NCREE Chiayi = NGA Chi-Chi04; NCREE Chi-Chi07 = NGA Chi-Chi06, based on identical hypocenters and event dates. | E41: 2026-09-10
A42: E06 | B42: Finite-fault derived fields | C42: FSP complete_inversion.fsp for each matched model | D42: Segment count and subfault counts verified against FSP. Model area = sum(LEN*WID); maximum slip = max(SLIP); rake_min/max are raw extrema, not a circular average. Model origin not catalog origin. | E42: 2026-09-10
A44: E07 | B44: UTC and identity audit | C44: https://earthquake.usgs.gov/fdsnws/event/1/ | D44: NGA matching independently checked within date +/- 1 day, 100 km and magnitude +/- 0.7; multi-candidate sequences resolved using origin time. Source HRMN is not uniformly UTC. | E44: 2026-09-10
A45: E08 | B45: CWA Taipo confirmation | C45: https://scweb.cwa.gov.tw/zh-tw/earthquake/imgs/2001091806444450101 | D45: 2001-09-18 06:44:44 Taiwan local = 2001-09-17 22:44:44 UTC; confirms Taipo identity independently of USGS catalog location. | E45: 2026-09-10
A46: E09 | B46: CWA Taitung confirmation | C46: https://scweb.cwa.gov.tw/zh-tw/earthquake/imgs/2007080908554757050 | D46: 2007-08-09 08:55:47 Taiwan local = 00:55:47 UTC; confirms Taitung identity. | E46: 2026-09-10
A48: E10 | B48: Calculated Yen(2025) Turkey R_hypo | C48: YEN!F90:F119; station coordinates: Pulse_records H/I via active row mapping | D48: R_hypo = SQRT(R_epi^2 + depth^2). R_epi: haversine great-circle distance, spherical Earth radius 6371 km. Hypocenter: same-row catalog latitude/longitude/depth (R:S:T). Station elevation assumed zero; local flat-depth approximation. Values calculated, not original published distances. Display 0.01 km is not accuracy. | E48: 2026-09-10
A50: E11 | B50: 有效主表範圍 | C50: S&B / NCREE / YEN -> Pulse_records | D50: 701筆。保留record_id與原source_sheet/source_row，新增active_sheet/active_row。排除Baker_moderate157、Kamai84、uncorrected fling34。Station_coords與repeat_count依有效記錄重算；YEN30筆計算Rhyp連動到主表。 | E50: 2026-09-10
A52: E12 | B52: User-provided earthquake Table 1 | C52: /Users/mingshen/Desktop/Screenshot 2026-09-10 at 23.58.23.png | D52: Screenshot Table 1, Summary of the Parameters of the Earthquakes Considered in This Work. Five events; Kumamoto mainshock has two strike/dip rows. Bibliographic citation absent. Selected parameters applied to YEN and shared event enrichment; USGS comparison/finite-fault values retained. | E52: 2026-09-10
... A63: IBURI_RHYP_UPDATE | B63: User-approved Iburi Rhyp replacement | C63: User message2026-09-11; FSP_IBURI | D63: Four YEN rows82:85 updated with sqrt(Repi²+depth²); Repi from6371km sphere; source42.6908N142.0067E depth37.04km; station elevation0. Native Rrup retained. Superseded Rhyp preserved in Distance_check AG665:AG668. | E63: 2026-09-11

Sheet Station_coords
A1: station_key | B1: station_names | C1: latitude_deg | D1: longitude_deg | E1: coord_status | F1: source_record_count | G1: source_sheets | H1: events | I1: coord_source_ids | J1: example_source_ref | K1: coord_note
A2: CN:deyangbaima | B2: Deyangbaima | C2: 31.3 | D2: 104.5 | E2: matched | F2: 1 | G2: S&B | H2: Wenchuan, China | I2: S02 | J2: ROTD50_d050 row 4717; RSN=4716; Deyangbaima
A3: CN:jiashi | B3: Jiashi | C3: 39.496 | D3: 76.739 | E3: matched | F3: 1 | G3: S&B | H3: Northwest China-03 | I3: S02 | J3: ROTD50_d050 row 1753; RSN=1752; Jiashi
A4: CN:mianzuqingping | B4: Mianzuqingping | C4: 31.5 | D4: 104.1 | E4: matched | F4: 1 | G4: S&B | H4: Wenchuan, China | I4: S02 | J4: ROTD50_d050 row 4817; RSN=4816; Mianzuqingping
A5: GR:kalamatabsmt2ndtrigger | B5: Kalamata (bsmt) (2nd trigger) | C5: 37.03 | D5: 22.12 | E5: matched | F5: 1 | G5: S&B | H5: Kalamata, Greece-02 | I5: S02 | J5: ROTD50_d050 row 567; RSN=566; Kalamata (bsmt) (2nd trigger)
A6: GR:kalamatabsmt2ndtrigger | B6: Kalamata (bsmt) (2nd trigger) | C6: 37.03 | D6: 22.12 | E6: original | F6: 1 | G6: NCREE | H6: 1986_Kalamata_02_Greece | I6: S01 | J6: Taiwan database(NCREE)!H27:I27
A7: IR:bam | B7: Bam | C7: 29.097 | D7: 58.353 | E7: matched | F7: 1 | G7: S&B | H7: Bam, Iran | I7: S02 | J7: ROTD50_d050 row 4041; RSN=4040; Bam
A8: IR:bam | B8: Bam | C8: 29.097 | D8: 58.353 | E8: original | F8: 1 | G8: NCREE | H8: 2003_Bam_Iran | I8: S01 | J8: Taiwan database(NCREE)!H183:I183
A9: IR:tabas | B9: Tabas | C9: 33.58 | D9: 56.92 | E9: matched | F9: 1 | G9: S&B | H9: Tabas, Iran | I9: S02 | J9: ROTD50_d050 row 144; RSN=143; Tabas
A10: IR:tabas | B10: Tabas | C10: 33.58 | D10: 56.92 | E10: original | F10: 1 | G10: NCREE | H10: 1978_Tabas_Iran | I10: S01 | J10: Taiwan database(NCREE)!H3:I3
A11: IT:bagnoliirpinio | B11: Bagnoli Irpinio | C11: 40.821 | D11: 15.069 | E11: matched | F11: 1 | G11: S&B | H11: Irpinia, Italy-01 | I11: S02 | J11: ROTD50_d050 row 286; RSN=285; Bagnoli Irpinio
A12: IT:bagnoliirpinio | B12: Bagnoli Irpinio | C12: 40.821 | D12: 15.069 | E12: original | F12: 1 | G12: NCREE | H12: 1980_Irpinia_01_Italy | I12: S01 | J12: Taiwan database(NCREE)!H22:I22
A13: IT:laquilaparking | B13: L'Aquila - Parking | C13: 42.345 | D13: 13.401 | E13: matched | F13: 1 | G13: S&B | H13: L'Aquila, Italy | I13: S02 | J13: ROTD50_d050 row 4484; RSN=4483; L'Aquila - Parking
... A20: IT:sturnostn | B20: Sturno (STN) | C20: 41.0184 | D20: 15.1117 | E20: original | F20: 1 | G20: NCREE | H20: 1980_Irpinia_01_Italy | I20: S01 | J20: Taiwan database(NCREE)!H23:I23
A21: JP:47004 | B21: 47004 | C21: 42.6226 | D21: 141.9204 | E21: matched | F21: 1 | G21: YEN | H21: Iburi | I21: U47004 | J21: User message 2026-09-11: lon141.9204 lat42.6226 | K21: User-provided coordinates; elevation unavailable.
A22: JP:93002 | B22: 93002 | C22: 32.968 | D22: 131.046 | E22: matched | F22: 1 | G22: YEN | H22: Kumamoto mainshock | I22: S03 | J22: line 96
A23: JP:93009 | B23: 93009 | C23: 32.822 | D23: 131.084 | E23: matched | F23: 1 | G23: YEN | H23: Kumamoto mainshock | I23: S03 | J23: line 101
A24: JP:93010 | B24: 93010 | C24: 32.819 | D24: 131.034 | E24: matched | F24: 1 | G24: YEN | H24: Kumamoto mainshock | I24: S03 | J24: line 102
A25: JP:93011 | B25: 93011 | C25: 32.856 | D25: 131.003 | E25: matched | F25: 1 | G25: YEN | H25: Kumamoto mainshock | I25: S03 | J25: line 103
A26: JP:93020 | B26: 93020 | C26: 32.643 | D26: 130.671 | E26: matched | F26: 2 | G26: YEN | H26: Kumamoto foreshock; Kumamoto mainshock | I26: S03 | J26: line 65
A27: JP:93021 | B27: 93021 | C27: 32.706 | D27: 130.731 | E27: matched | F27: 1 | G27: YEN | H27: Kumamoto foreshock | I27: S03 | J27: line 66
A28: JP:93024 | B28: 93024 | C28: 32.589 | D28: 130.707 | E28: matched | F28: 1 | G28: YEN | H28: Kumamoto foreshock | I28: S03 | J28: line 106
A29: JP:93025 | B29: 93025 | C29: 32.636 | D29: 130.752 | E29: matched | F29: 2 | G29: YEN | H29: Kumamoto foreshock; Kumamoto mainshock | I29: S03 | J29: line 68
A30: JP:93029 | B30: 93029 | C30: 32.874 | D30: 130.558 | E30: matched | F30: 1 | G30: YEN | H30: Kumamoto mainshock | I30: S03 | J30: line 108
A31: JP:93030 | B31: 93030 | C31: 32.861 | D31: 130.595 | E31: matched | F31: 1 | G31: YEN | H31: Kumamoto mainshock | I31: S03 | J31: line 109
A32: JP:93041 | B32: 93041 | C32: 32.966 | D32: 130.767 | E32: matched | F32: 1 | G32: YEN | H32: Kumamoto mainshock | I32: S03 | J32: line 118
A33: JP:93042 | B33: 93042 | C33: 32.943 | D33: 130.858 | E33: matched | F33: 1 | G33: YEN | H33: Kumamoto mainshock | I33: S03 | J33: line 119
... A77: JP:portisland0m | B77: Port Island (0 m) | C77: 34.67 | D77: 135.201 | E77: original | F77: 1 | G77: NCREE | H77: 1995_Kobe_Japan | I77: S01 | J77: Taiwan database(NCREE)!H59:I59
A78: JP:portisland83m | B78: Port Island (83 m) | E78: unresolved | F78: 1 | G78: S&B | H78: Kobe, Japan | K78: 未找到可確定對應的座標。
A79: JP:servicehall24mdepth | B79: SERVICE HALL: 2.4 M DEPTH | C79: 37.4267 | D79: 138.6083 | E79: matched | F79: 1 | G79: S&B | H79: Chuetsu-oki | I79: S02 | J79: ROTD50_d050 row 4897; RSN=4896; Kashiwazaki NPP, Service Hall Array 2.4 m depth
A80: JP:servicehall508mdepth | B80: SERVICE HALL:50.8 M DEPTH | E80: unresolved | F80: 1 | G80: S&B | H80: Chuetsu-oki | K80: 未找到可確定對應的座標。
A81: JP:takarazuka | B81: Takarazuka | C81: 34.809 | D81: 135.344 | E81: matched | F81: 1 | G81: S&B | H81: Kobe, Japan | I81: S02 | J81: ROTD50_d050 row 1120; RSN=1119; Takarazuka
A82: JP:takarazuka | B82: Takarazuka | C82: 34.809 | D82: 135.344 | E82: original | F82: 1 | G82: NCREE | H82: 1995_Kobe_Japan | I82: S01 | J82: Taiwan database(NCREE)!H60:I60
A83: JP:takatori | B83: Takatori | C83: 34.649 | D83: 135.139 | E83: matched | F83: 1 | G83: S&B | H83: Kobe, Japan | I83: S02 | J83: ROTD50_d050 row 1121; RSN=1120; Takatori
A84: JP:takatori | B84: Takatori | C84: 34.649 | D84: 135.139 | E84: original | F84: 1 | G84: NCREE | H84: 1995_Kobe_Japan | I84: S01 | J84: Taiwan database(NCREE)!H61:I61
A85: JP:ttr008 | B85: TTR008 | C85: 35.4227 | D85: 133.3327 | E85: matched | F85: 1 | G85: S&B | H85: Tottori, Japan | I85: S02 | J85: ROTD50_d050 row 3966; RSN=3965; TTR008
A86: JP:ttr008 | B86: TTR008 | C86: 35.4227 | D86: 133.3327 | E86: original | F86: 1 | G86: NCREE | H86: 2000_Tottori_Japan | I86: S01 | J86: Taiwan database(NCREE)!H168:I168
A87: JP:yansakuramachicitywatershed | B87: Yan Sakuramachi City watershed | C87: 37.6233 | D87: 138.8428 | E87: matched | F87: 1 | G87: S&B | H87: Chuetsu-oki | I87: S02 | J87: ROTD50_d050 row 4880; RSN=4879; Yan Sakuramachi City watershed
A88: JP:yoshikawakujoetsucity | B88: Yoshikawaku Joetsu City | C88: 37.2203 | D88: 138.4081 | E88: matched | F88: 1 | G88: S&B | H88: Chuetsu-oki | I88: S02 | J88: ROTD50_d050 row 4851; RSN=4850; Yoshikawaku Joetsu City
A89: ME:barskupstinaopstine | B89: Bar-Skupstina Opstine | C89: 42.095 | D89: 19.101 | E89: matched | F89: 1 | G89: S&B | H89: Montenegro, Yugo. | I89: S02 | J89: ROTD50_d050 row 4452; RSN=4451; Bar-Skupstina Opstine
...

Sheet Event_sources
A1: event_key | B1: event_names | C1: table_magnitudes | D1: source_status | E1: origin_date_utc | F1: origin_time_utc | G1: time_precision | H1: catalog_magnitude | I1: magnitude_type | J1: hypo_latitude_deg | K1: hypo_longitude_deg | L1: hypo_depth_km | M1: mechanism | N1: plane_definition | O1: strike1_deg | P1: dip1_deg | Q1: rake1_deg | R1: strike2_deg | S1: dip2_deg | T1: rake2_deg | U1: origin_source | V1: mechanism_source | W1: usgs_event_id | X1: source_url | Y1: nga_reference | Z1: nga_finite_fault_flag | AA1: nga_fault_name | AB1: nga_strike_deg | AC1: nga_dip_deg | AD1: nga_rake_deg | AE1: nga_ztor_km | AF1: nga_length_km | AG1: nga_width_km | AH1: ff_status | AI1: notes | AJ1: retrieved_date | AK1: ff_segment_count | AL1: ff_model_Mw | AM1: ff_moment_Nm | AN1: ff_max_slip_m | AO1: ff_model_area_km2 | AP1: ff_average_rise_s | AQ1: ff_average_rupture_velocity_km_s | AR1: ff_model_hypo_lat | AS1: ff_model_hypo_lon | AT1: ff_model_hypo_depth_km | AU1: ff_product_source | AV1: ff_product_code | AW1: ff_version | AX1: ff_updated_utc | AY1: ff_url | AZ1: ff_fsp_url | BA1: ff_param_url | BB1: ff_moment_rate_url | BC1: match_basis | BD1: time_source_url | BE1: source_scope | BF1: event_source_key
A2: 1954_northerncalif3 | B2: Northern Calif-03 | C2: 6.5 | D2: Original NGA source preferred | E2: 1954-12-21 | F2: 19:56:29.630Z | G2: USGS catalog timestamp | H2: 6.5 | I2: U | J2: 40.8167 | K2: -124.083 | L2: 10 | M2: Strike slip | N2: NGA-West2 representative fault plane | O2: 65.6 | P2: 90 | Q2: 0 | U2: Original NGA-West2 event metadata (coordinates, depth, magnitude); UTC time independently audited | V2: Original NGA-West2 strike/dip/rake | W2: iscgem891371 | X2: https://peer.berkeley.edu/node/74 | Y2: Updated NGA-West2 RotD50 d050 public flatfile; row 21; EQID 0017 | Z2: 0 | AB2: 65.6 | AC2: 90 | AD2: 0 | AE2: 4.008 | AF2: 14.9 | AG2: 9.1 | AH2: No matching USGS product in queried archive | AI2: Original NGA source parameters restored for S&B distances. USGS identity/time and finite-fault products are separate. Flatfile mirror provenance: Sources_method E03/E04. | AJ2: 2026-09-10 | BC2: NGA event name/year and EQID; USGS date, magnitude and location; sequence distinguished by origin time. | BD2: https://earthquake.usgs.gov/earthquakes/eventpage/iscgem891371 | BE2: S&B | BF2: S&B::1954_northerncalif3
A3: 1971_sanfernando | B3: San Fernando | 1971_SanFernando_USA | C3: 6.6 | D3: Original NGA source preferred | E3: 1971-02-09 | F3: 14:00:41.920Z | G3: USGS catalog timestamp | H3: 6.61 | I3: Mw | J3: 34.44 | K3: -118.41 | L3: 13 | M3: Reverse-oblique | N3: NGA-West2 representative fault plane | O3: 288 | P3: 50 | Q3: 83 | U3: Original NGA-West2 event metadata (coordinates, depth, magnitude); UTC time independently audited | V3: Original NGA-West2 strike/dip/rake | W3: ci3347678 | X3: https://peer.berkeley.edu/node/74 | Y3: Updated NGA-West2 RotD50 d050 public flatfile; row 52; EQID 0030 | Z3: 1 | AA3: Sierra Madre-San Fernando | AB3: 288 | AC3: 50 | AD3: 83 | AE3: 0 | AF3: 20 | AG3: 27.4 | AH3: No matching USGS product in queried archive | AI3: Original NGA source parameters restored for S&B distances. USGS identity/time and finite-fault products are separate. Flatfile mirror provenance: Sources_method E03/E04. | AJ3: 2026-09-10 | BC3: NGA event name/year and EQID; USGS date, magnitude and location; sequence distinguished by origin time. | BD3: https://earthquake.usgs.gov/earthquakes/eventpage/ci3347678 | BE3: S&B | BF3: S&B::1971_sanfernando
A4: 1978_tabas | B4: Tabas, Iran | 1978_Tabas_Iran | C4: 7.3 | 7.4 | D4: Original NGA source preferred | E4: 1978-09-16 | F4: 15:35:56.600Z | G4: USGS catalog timestamp | H4: 7.35 | I4: Mw | J4: 33.215 | K4: 57.323 | L4: 5.75 | M4: Reverse-oblique | N4: NGA-West2 representative fault plane | O4: 330 | P4: 25 | Q4: 110 | U4: Original NGA-West2 event metadata (coordinates, depth, magnitude); UTC time independently audited | V4: Original NGA-West2 strike/dip/rake | W4: usp0000wjx | X4: https://peer.berkeley.edu/node/74 | Y4: Updated NGA-West2 RotD50 d050 public flatfile; row 138; EQID 0046 | Z4: 1 | AB4: 330 | AC4: 25 | AD4: 110 | AE4: 1 | AF4: 90 | AG4: 35 | AH4: No matching USGS product in queried archive | AI4: Original NGA source parameters restored for S&B distances. USGS identity/time and finite-fault products are separate. Flatfile mirror provenance: Sources_method E03/E04. | AJ4: 2026-09-10 | BC4: NGA event name/year and EQID; USGS date, magnitude and location; sequence distinguished by origin time. | BD4: https://earthquake.usgs.gov/earthquakes/eventpage/usp0000wjx | BE4: S&B | BF4: S&B::1978_tabas
A5: 1979_montenegro | B5: Montenegro, Yugo. | 1979_Montenegro_Yugoslavia | C5: 7.1 | D5: Original NGA source preferred | E5: 1979-04-15 | F5: 06:19:44.100Z | G5: USGS catalog timestamp | H5: 7.1 | I5: Mw | J5: 42.04 | K5: 19.21 | L5: 7 | M5: Reverse-oblique | N5: NGA-West2 representative fault plane | O5: 300 | P5: 14 | Q5: 88 | U5: Original NGA-West2 event metadata (coordinates, depth, magnitude); UTC time independently audited | V5: Original NGA-West2 strike/dip/rake | W5: usp000100b | X5: https://peer.berkeley.edu/node/74 | Y5: Updated NGA-West2 RotD50 d050 public flatfile; row 4452; EQID 0262 | Z5: 1 | AB5: 300 | AC5: 14 | AD5: 88 | AE5: 3.61 | AF5: 54 | AG5: 34 | AH5: No matching USGS product in queried archive | AI5: Original NGA source parameters restored for S&B distances. USGS identity/time and finite-fault products are separate. Flatfile mirror provenance: Sources_method E03/E04. | AJ5: 2026-09-10 | BC5: NGA event name/year and EQID; USGS date, magnitude and location; sequence distinguished by origin time. | BD5: https://earthquake.usgs.gov/earthquakes/eventpage/usp000100b | BE5: S&B | BF5: S&B::1979_montenegro
A6: 1979_coyotelake | B6: Coyote Lake | 1979_CoyoteLake_USA | C6: 5.7 | D6: Original NGA source preferred | E6: 1979-08-06 | F6: 17:05:22.930Z | G6: USGS catalog timestamp | H6: 5.74 | I6: Mw | J6: 37.065 | K6: -121.49 | L6: 8 | M6: Strike slip | N6: NGA-West2 representative fault plane | O6: 336 | P6: 80 | Q6: 176 | U6: Original NGA-West2 event metadata (coordinates, depth, magnitude); UTC time independently audited | V6: Original NGA-West2 strike/dip/rake | W6: nc1046962 | X6: https://peer.berkeley.edu/node/74 | Y6: Updated NGA-West2 RotD50 d050 public flatfile; row 146; EQID 0048 | Z6: 1 | AA6: Calaveras fault south | AB6: 336 | AC6: 80 | AD6: 176 | AE6: 3.08 | AF6: 6.6 | AG6: 7 | AH6: No matching USGS product in queried archive | AI6: Original NGA source parameters restored for S&B distances. USGS identity/time and finite-fault products are separate. Flatfile mirror provenance: Sources_method E03/E04. | AJ6: 2026-09-10 | BC6: NGA event name/year and EQID; USGS date, magnitude and location; sequence distinguished by origin time. | BD6: https://earthquake.usgs.gov/earthquakes/eventpage/nc1046962 | BE6: S&B | BF6: S&B::1979_coyotelake
A7: 1979_imperialvalley6 | B7: Imperial Valley-06 | 1979_ImperialValley_06_USA | C7: 6.5 | D7: Original NGA source preferred | E7: 1979-10-15 | F7: 23:16:53.910Z | G7: USGS catalog timestamp | H7: 6.53 | I7: Mw | J7: 32.644 | K7: -115.307 | L7: 9.96 | M7: Strike slip | N7: NGA-West2 representative fault plane | O7: 323 | P7: 80 | Q7: 180 | U7: Original NGA-West2 event metadata (coordinates, depth, magnitude); UTC time independently audited | V7: Original NGA-West2 strike/dip/rake | W7: ci3352060 | X7: https://peer.berkeley.edu/node/74 | Y7: Updated NGA-West2 RotD50 d050 public flatfile; row 159; EQID 0050 | Z7: 1 | AA7: Imperial fault | AB7: 323 | AC7: 80 | AD7: 180 | AE7: 0 | AF7: 50 | AG7: 13 | AH7: No matching USGS product in queried archive | AI7: Original NGA source parameters restored for S&B distances. USGS identity/time and finite-fault products are separate. Flatfile mirror provenance: Sources_method E03/E04. | AJ7: 2026-09-10 | BC7: NGA event name/year and EQID; USGS date, magnitude and location; sequence distinguished by origin time. | BD7: https://earthquake.usgs.gov/earthquakes/eventpage/ci3352060 | BE7: S&B | BF7: S&B::1979_imperialvalley6
A8: 1979_imperialvalley7 | B8: Imperial Valley-07 | C8: 5 | D8: Original NGA source preferred | E8: 1979-10-15 | F8: 23:19:29.980Z | G8: USGS catalog timestamp | H8: 5.01 | I8: Mw | J8: 32.7667 | K8: -115.4413 | L8: 9.5 | M8: Strike slip | N8: NGA-West2 representative fault plane | O8: 319.9 | P8: 90 | Q8: 180 | U8: Original NGA-West2 event metadata (coordinates, depth, magnitude); UTC time independently audited | V8: Original NGA-West2 strike/dip/rake | W8: ci9712718 | X8: https://peer.berkeley.edu/node/74 | Y8: Updated NGA-West2 RotD50 d050 public flatfile; row 194; EQID 0051 | Z8: 0 | AB8: 319.9 | AC8: 90 | AD8: 180 | AE8: 7.261 | AF8: 3.6 | AG8: 4.2 | AH8: No matching USGS product in queried archive | AI8: Original NGA source parameters restored for S&B distances. USGS identity/time and finite-fault products are separate. Flatfile mirror provenance: Sources_method E03/E04. | AJ8: 2026-09-10 | BC8: NGA event name/year and EQID; USGS date, magnitude and location; sequence distinguished by origin time. | BD8: https://earthquake.usgs.gov/earthquakes/eventpage/ci9712718 | BE8: S&B | BF8: S&B::1979_imperialvalley7
A9: 1980_irpinia1 | B9: Irpinia, Italy-01 | 1980_Irpinia_01_Italy | C9: 6.9 | D9: Original NGA source preferred | E9: 1980-11-23 | F9: 18:34:53.800Z | G9: USGS catalog timestamp | H9: 6.9 | I9: Mw | J9: 40.8059 | K9: 15.3372 | L9: 9.5 | M9: Normal | N9: NGA-West2 representative fault plane | O9: 312.8 | P9: 60 | Q9: -90 | U9: Original NGA-West2 event metadata (coordinates, depth, magnitude); UTC time independently audited | V9: Original NGA-West2 strike/dip/rake | W9: usp0001ay4 | X9: https://peer.berkeley.edu/node/74 | Y9: Updated NGA-West2 RotD50 d050 public flatfile; row 284; EQID 0068 | Z9: 1 | AB9: 312.8 | AC9: 60 | AD9: -90 | AE9: 0 | AF9: 47 | AG9: 15 | AH9: No matching USGS product in queried archive | AI9: Original NGA source parameters restored for S&B distances. USGS identity/time and finite-fault products are separate. Flatfile mirror provenance: Sources_method E03/E04. | AJ9: 2026-09-10 | BC9: NGA event name/year and EQID; USGS date, magnitude and location; sequence distinguished by origin time. | BD9: https://earthquake.usgs.gov/earthquakes/eventpage/usp0001ay4 | BE9: S&B | BF9: S&B::1980_irpinia1
A10: 1980_mammothlakes6 | B10: Mammoth Lakes-06 | C10: 5.9 | D10: Original NGA source preferred | E10: 1980-05-27 | F10: 14:50:56.810Z | G10: USGS catalog timestamp | H10: 5.94 | I10: Mw | J10: 37.506 | K10: -118.826 | L10: 14 | M10: Strike slip | N10: NGA-West2 representative fault plane | O10: 22 | P10: 50 | Q10: -28 | U10: Original NGA-West2 event metadata (coordinates, depth, magnitude); UTC time independently audited | V10: Original NGA-West2 strike/dip/rake | W10: nc1053177 | X10: https://peer.berkeley.edu/node/74 | Y10: Updated NGA-West2 RotD50 d050 public flatfile; row 247; EQID 0061 | Z10: 0 | AB10: 22 | AC10: 50 | AD10: -28 | AE10: 10.578 | AF10: 9.2 | AG10: 5.3 | AH10: No matching USGS product in queried archive | AI10: Original NGA source parameters restored for S&B distances. USGS identity/time and finite-fault products are separate. Flatfile mirror provenance: Sources_method E03/E04. | AJ10: 2026-09-10 | BC10: NGA event name/year and EQID; USGS date, magnitude and location; sequence distinguished by origin time. | BD10: https://earthquake.usgs.gov/earthquakes/eventpage/nc1053177 | BE10: S&B | BF10: S&B::1980_mammothlakes6
A11: 1981_westmorland | B11: Westmorland | 1981_Westmorland_USA | C11: 5.9 | D11: Original NGA source preferred | E11: 1981-04-26 | F11: 12:09:28.290Z | G11: USGS catalog timestamp | H11: 5.9 | I11: Mw | J11: 33.1 | K11: -115.62 | L11: 2.3 | M11: Strike slip | N11: NGA-West2 representative fault plane | O11: 64 | P11: 90 | Q11: 0 | U11: Original NGA-West2 event metadata (coordinates, depth, magnitude); UTC time independently audited | V11: Original NGA-West2 strike/dip/rake | W11: ci514869 | X11: https://peer.berkeley.edu/node/74 | Y11: Updated NGA-West2 RotD50 d050 public flatfile; row 315; EQID 0073 | Z11: 1 | AB11: 64 | AC11: 90 | AD11: 0 | AE11: 2 | AF11: 10 | AG11: 7 | AH11: No matching USGS product in queried archive | AI11: Original NGA source parameters restored for S&B distances. USGS identity/time and finite-fault products are separate. Flatfile mirror provenance: Sources_method E03/E04. | AJ11: 2026-09-10 | BC11: NGA event name/year and EQID; USGS date, magnitude and location; sequence distinguished by origin time. | BD11: https://earthquake.usgs.gov/earthquakes/eventpage/ci514869 | BE11: S&B | BF11: S&B::1981_westmorland
A12: 1983_coalinga2 | B12: Coalinga-02 | C12: 5.1 | D12: Original NGA source preferred | E12: 1983-05-09 | F12: 02:49:11.540Z | G12: USGS catalog timestamp | H12: 5.09 | I12: Mw | J12: 36.246 | K12: -120.299 | L12: 12 | M12: Reverse-oblique | N12: NGA-West2 representative fault plane | O12: 136 | P12: 44 | Q12: 106 | U12: Original NGA-West2 event metadata (coordinates, depth, magnitude); UTC time independently audited | V12: Original NGA-West2 strike/dip/rake | W12: nc1093715 | X12: https://peer.berkeley.edu/node/74 | Y12: Updated NGA-West2 RotD50 d050 public flatfile; row 371; EQID 0077 | Z12: 0 | AB12: 136 | AC12: 44 | AD12: 106 | AE12: 10.55 | AF12: 4.1 | AG12: 4.6 | AH12: No matching USGS product in queried archive | AI12: Original NGA source parameters restored for S&B distances. USGS identity/time and finite-fault products are separate. Flatfile mirror provenance: Sources_method E03/E04. | AJ12: 2026-09-10 | BC12: NGA event name/year and EQID; USGS date, magnitude and location; sequence distinguished by origin time. | BD12: https://earthquake.usgs.gov/earthquakes/eventpage/nc1093715 | BE12: S&B | BF12: S&B::1983_coalinga2
A13: 1983_coalinga5 | B13: Coalinga-05 | C13: 5.8 | D13: Original NGA source preferred | E13: 1983-07-22 | F13: 02:39:53.960Z | G13: USGS catalog timestamp | H13: 5.77 | I13: Mw | J13: 36.241 | K13: -120.409 | L13: 7.4 | M13: Reverse-oblique | N13: NGA-West2 representative fault plane | O13: 355 | P13: 38 | Q13: 102 | U13: Original NGA-West2 event metadata (coordinates, depth, magnitude); UTC time independently audited | V13: Original NGA-West2 strike/dip/rake | W13: nc1098982 | X13: https://peer.berkeley.edu/node/74 | Y13: Updated NGA-West2 RotD50 d050 public flatfile; row 406; EQID 0080 | Z13: 0 | AB13: 355 | AC13: 38 | AD13: 102 | AE13: 5.414 | AF13: 6.3 | AG13: 6.1 | AH13: No matching USGS product in queried archive | AI13: Original NGA source parameters restored for S&B distances. USGS identity/time and finite-fault products are separate. Flatfile mirror provenance: Sources_method E03/E04. | AJ13: 2026-09-10 | BC13: NGA event name/year and EQID; USGS date, magnitude and location; sequence distinguished by origin time. | BD13: https://earthquake.usgs.gov/earthquakes/eventpage/nc1098982 | BE13: S&B | BF13: S&B::1983_coalinga5
A14: 1983_coalinga7 | B14: Coalinga-07 | C14: 5.2 | D14: Original NGA source preferred | E14: 1983-07-25 | F14: 22:31:39.480Z | G14: USGS catalog timestamp | H14: 5.21 | I14: Mw | J14: 36.229 | K14: -120.398 | L14: 8.4 | M14: Reverse-oblique | N14: NGA-West2 representative fault plane | O14: 348.1 | P14: 38 | Q14: 90 | U14: Original NGA-West2 event metadata (coordinates, depth, magnitude); UTC time independently audited | V14: Original NGA-West2 strike/dip/rake | W14: nc1099288 | X14: https://peer.berkeley.edu/node/74 | Y14: Updated NGA-West2 RotD50 d050 public flatfile; row 419; EQID 0082 | Z14: 0 | AB14: 348.1 | AC14: 38 | AD14: 90 | AE14: 7.127 | AF14: 4.5 | AG14: 4.6 | AH14: No matching USGS product in queried archive | AI14: Original NGA source parameters restored for S&B distances. USGS identity/time and finite-fault products are separate. Flatfile mirror provenance: Sources_method E03/E04. | AJ14: 2026-09-10 | BC14: NGA event name/year and EQID; USGS date, magnitude and location; sequence distinguished by origin time. | BD14: https://earthquake.usgs.gov/earthquakes/eventpage/nc1099288 | BE14: S&B | BF14: S&B::1983_coalinga7
A15: 1984_morganhill | B15: Morgan Hill | 1984_MorganHill_USA | C15: 6.2 | D15: Original NGA source preferred | E15: 1984-04-24 | F15: 21:15:18.760Z | G15: USGS catalog timestamp | H15: 6.19 | I15: Mw | J15: 37.306 | K15: -121.695 | L15: 8.5 | M15: Strike slip | N15: NGA-West2 representative fault plane | O15: 148 | P15: 90 | Q15: 180 | U15: Original NGA-West2 event metadata (coordinates, depth, magnitude); UTC time independently audited | V15: Original NGA-West2 strike/dip/rake | W15: nc17204 | X15: https://peer.berkeley.edu/node/74 | Y15: Updated NGA-West2 RotD50 d050 public flatfile; row 447; EQID 0090 | Z15: 1 | AA15: Calaveras fault south | AB15: 148 | AC15: 90 | AD15: 180 | AE15: 0.5 | AF15: 27 | AG15: 11.5 | AH15: No matching USGS product in queried archive | AI15: Original NGA source parameters restored for S&B distances. USGS identity/time and finite-fault products are separate. Flatfile mirror provenance: Sources_method E03/E04. | AJ15: 2026-09-10 | BC15: NGA event name/year and EQID; USGS date, magnitude and location; sequence distinguished by origin time. | BD15: https://earthquake.usgs.gov/earthquakes/eventpage/nc17204 | BE15: S&B | BF15: S&B::1984_morganhill
A16: 1986_kalamata2 | B16: Kalamata, Greece-02 | 1986_Kalamata_02_Greece | C16: 5.4 | D16: Original NGA source preferred | E16: 1986-09-15 | F16: 11:41:27.860Z | G16: USGS catalog timestamp | H16: 5.4 | I16: MS | J16: 37.08 | K16: 22.07 | L16: 5 | M16: Normal | N16: NGA-West2 representative fault plane | O16: 332.3 | P16: 55 | Q16: -90 | U16: Original NGA-West2 event metadata (coordinates, depth, magnitude); UTC time independently audited | V16: Original NGA-West2 strike/dip/rake | W16: usp0002y3u | X16: https://peer.berkeley.edu/node/74 | Y16: Updated NGA-West2 RotD50 d050 public flatfile; row 566; EQID 0107 | Z16: 0 | AB16: 332.3 | AC16: 55 | AD16: -90 | AE16: 2.603 | AF16: 6.3 | AG16: 3.9 | AH16: No matching USGS product in queried archive | AI16: Original NGA source parameters restored for S&B distances. USGS identity/time and finite-fault products are separate. Flatfile mirror provenance: Sources_method E03/E04. | AJ16: 2026-09-10 | BC16: NGA event name/year and EQID; USGS date, magnitude and location; sequence distinguished by origin time. | BD16: https://earthquake.usgs.gov/earthquakes/eventpage/usp0002y3u | BE16: S&B | BF16: S&B::1986_kalamata2
A17: 1986_npalmsprings | B17: N. Palm Springs | C17: 6.1 | D17: Original NGA source preferred | E17: 1986-07-08 | F17: 09:20:44.560Z | G17: USGS catalog timestamp | H17: 6.06 | I17: Mw | J17: 34 | K17: -116.6117 | L17: 11 | M17: Reverse-oblique | N17: NGA-West2 representative fault plane | O17: 287 | P17: 46 | Q17: 150 | U17: Original NGA-West2 event metadata (coordinates, depth, magnitude); UTC time independently audited | V17: Original NGA-West2 strike/dip/rake | W17: ci700917 | X17: https://peer.berkeley.edu/node/74 | Y17: Updated NGA-West2 RotD50 d050 public flatfile; row 512; EQID 0101 | Z17: 1 | AA17: San Andreas fault, southern section | AB17: 287 | AC17: 46 | AD17: 150 | AE17: 4 | AF17: 20 | AG17: 13.3 | AH17: No matching USGS product in queried archive | AI17: Original NGA source parameters restored for S&B distances. USGS identity/time and finite-fault products are separate. Flatfile mirror provenance: Sources_method E03/E04. | AJ17: 2026-09-10 | BC17: NGA event name/year and EQID; USGS date, magnitude and location; sequence distinguished by origin time. | BD17: https://earthquake.usgs.gov/earthquakes/eventpage/ci700917 | BE17: S&B | BF17: S&B::1986_npalmsprings
A18: 1986_smart140 | B18: Taiwan SMART1(40) | C18: 6.3 | D18: Original NGA source preferred | E18: 1986-05-20 | F18: 05:25:46.960Z | G18: USGS catalog timestamp | H18: 6.32 | I18: Mw | J18: 24.0817 | K18: 121.5915 | L18: 15.8 | M18: Reverse-oblique | N18: NGA-West2 representative fault plane | O18: 43 | P18: 57 | Q18: 100 | U18: Original NGA-West2 event metadata (coordinates, depth, magnitude); UTC time independently audited | V18: Original NGA-West2 strike/dip/rake | W18: usp0002u79 | X18: https://peer.berkeley.edu/node/74 | Y18: Updated NGA-West2 RotD50 d050 public flatfile; row 504; EQID 0100 | Z18: 0 | AB18: 43 | AC18: 57 | AD18: 100 | AE18: 12.09 | AF18: 13.8 | AG18: 11.8 | AH18: No matching USGS product in queried archive | AI18: Original NGA source parameters restored for S&B distances. USGS identity/time and finite-fault products are separate. Flatfile mirror provenance: Sources_method E03/E04. | AJ18: 2026-09-10 | BC18: NGA event name/year and EQID; USGS date, magnitude and location; sequence distinguished by origin time. | BD18: https://earthquake.usgs.gov/earthquakes/eventpage/usp0002u79 | BE18: S&B | BF18: S&B::1986_smart140
A19: 1986_sansalvador | B19: San Salvador | 1986_SanSalvador_USA | C19: 5.8 | D19: Original NGA source preferred | E19: 1986-10-10 | F19: 17:49:24.100Z | G19: USGS catalog timestamp | H19: 5.8 | I19: Mw | J19: 13.633 | K19: -89.2 | L19: 10.9 | M19: Strike slip | N19: NGA-West2 representative fault plane | O19: 32 | P19: 85 | Q19: 0 | U19: Original NGA-West2 event metadata (coordinates, depth, magnitude); UTC time independently audited | V19: Original NGA-West2 strike/dip/rake | W19: usp0002yu9 | X19: https://peer.berkeley.edu/node/74 | Y19: Updated NGA-West2 RotD50 d050 public flatfile; row 569; EQID 0108 | Z19: 1 | AB19: 32 | AC19: 85 | AD19: 0 | AE19: 5.92 | AF19: 8 | AG19: 7 | AH19: No matching USGS product in queried archive | AI19: Original NGA source parameters restored for S&B distances. USGS identity/time and finite-fault products are separate. Flatfile mirror provenance: Sources_method E03/E04. | AJ19: 2026-09-10 | BC19: NGA event name/year and EQID; USGS date, magnitude and location; sequence distinguished by origin time. | BD19: https://earthquake.usgs.gov/earthquakes/eventpage/usp0002yu9 | BE19: S&B | BF19: S&B::1986_sansalvador
A20: 1987_whittiernarrows1 | B20: Whittier Narrows-01 | C20: 6 | D20: Original NGA source preferred | E20: 1987-10-01 | F20: 14:42:20.020Z | G20: USGS catalog timestamp | H20: 5.99 | I20: Mw | J20: 34.0493 | K20: -118.081 | L20: 14.6 | M20: Reverse-oblique | N20: NGA-West2 representative fault plane | O20: 280 | P20: 30 | Q20: 150 | U20: Original NGA-West2 event metadata (coordinates, depth, magnitude); UTC time independently audited | V20: Original NGA-West2 strike/dip/rake | W20: ci731691 | X20: https://peer.berkeley.edu/node/74 | Y20: Updated NGA-West2 RotD50 d050 public flatfile; row 590; EQID 0113 | Z20: 1 | AA20: Puente Hills Blind Thrust | AB20: 280 | AC20: 30 | AD20: 150 | AE20: 14.5 | AF20: 10 | AG20: 6 | AH20: No matching USGS product in queried archive | AI20: Original NGA source parameters restored for S&B distances. USGS identity/time and finite-fault products are separate. Flatfile mirror provenance: Sources_method E03/E04. | AJ20: 2026-09-10 | BC20: NGA event name/year and EQID; USGS date, magnitude and location; sequence distinguished by origin time. | BD20: https://earthquake.usgs.gov/earthquakes/eventpage/ci731691 | BE20: S&B | BF20: S&B::1987_whittiernarrows1
A21: 1987_superstitionhills2 | B21: Superstition Hills-02 | 1987_SuperstitionHills_02_USA | C21: 6.5 | D21: Original NGA source preferred | E21: 1987-11-24 | F21: 13:15:56.710Z | G21: USGS catalog timestamp | H21: 6.54 | I21: Mw | J21: 33.0222 | K21: -115.8314 | L21: 9 | M21: Strike slip | N21: NGA-West2 representative fault plane | O21: 127 | P21: 90 | Q21: 180 | U21: Original NGA-West2 event metadata (coordinates, depth, magnitude); UTC time independently audited | V21: Original NGA-West2 strike/dip/rake | W21: ci628016 | X21: https://peer.berkeley.edu/node/74 | Y21: Updated NGA-West2 RotD50 d050 public flatfile; row 720; EQID 0116 | Z21: 1 | AA21: Superstition Hills fault | AB21: 127 | AC21: 90 | AD21: 180 | AE21: 0 | AF21: 20 | AG21: 12 | AH21: No matching USGS product in queried archive | AI21: Original NGA source parameters restored for S&B distances. USGS identity/time and finite-fault products are separate. Flatfile mirror provenance: Sources_method E03/E04. | AJ21: 2026-09-10 | BC21: NGA event name/year and EQID; USGS date, magnitude and location; sequence distinguished by origin time. | BD21: https://earthquake.usgs.gov/earthquakes/eventpage/ci628016 | BE21: S&B | BF21: S&B::1987_superstitionhills2
A22: 1989_lomaprieta | B22: Loma Prieta | 1989_LomaPrieta_USA | C22: 6.9 | D22: Original NGA source preferred | E22: 1989-10-18 | F22: 00:04:15.190Z | G22: USGS catalog timestamp | H22: 6.93 | I22: Mw | J22: 37.0407 | K22: -121.8829 | L22: 17.48 | M22: Reverse-oblique | N22: NGA-West2 representative fault plane | O22: 128 | P22: 70 | Q22: 140 | U22: Original NGA-West2 event metadata (coordinates, depth, magnitude); UTC time independently audited | V22: Original NGA-West2 strike/dip/rake | W22: nc216859 | X22: https://peer.berkeley.edu/node/74 | Y22: Updated NGA-West2 RotD50 d050 public flatfile; row 732; EQID 0118 | Z22: 1 | AA22: San Andreas-Santa Cruz | AB22: 128 | AC22: 70 | AD22: 140 | AE22: 3.85 | AF22: 40 | AG22: 18 | AH22: No matching USGS product in queried archive | AI22: Original NGA source parameters restored for S&B distances. USGS identity/time and finite-fault products are separate. Flatfile mirror provenance: Sources_method E03/E04. | AJ22: 2026-09-10 | BC22: NGA event name/year and EQID; USGS date, magnitude and location; sequence distinguished by origin time. | BD22: https://earthquake.usgs.gov/earthquakes/eventpage/nc216859 | BE22: S&B | BF22: S&B::1989_lomaprieta
A23: 1992_capemendocino | B23: Cape Mendocino | 1992_CapeMendocino_USA | C23: 7 | D23: Original NGA source preferred | E23: 1992-04-25 | F23: 18:06:05.180Z | G23: USGS catalog timestamp | H23: 7.01 | I23: Mw | J23: 40.327 | K23: -124.233 | L23: 9.5 | M23: Reverse-oblique | N23: NGA-West2 representative fault plane | O23: 350 | P23: 14 | Q23: 105 | U23: Original NGA-West2 event metadata (coordinates, depth, magnitude); UTC time independently audited | V23: Original NGA-West2 strike/dip/rake | W23: nc269151 | X23: https://peer.berkeley.edu/node/74 | Y23: Updated NGA-West2 RotD50 d050 public flatfile; row 826; EQID 0123 | Z23: 1 | AA23: Cascadia Subduction Zone | AB23: 350 | AC23: 14 | AD23: 105 | AE23: 5.2 | AF23: 20 | AG23: 28 | AH23: No matching USGS product in queried archive | AI23: Original NGA source parameters restored for S&B distances. USGS identity/time and finite-fault products are separate. Flatfile mirror provenance: Sources_method E03/E04. | AJ23: 2026-09-10 | BC23: NGA event name/year and EQID; USGS date, magnitude and location; sequence distinguished by origin time. | BD23: https://earthquake.usgs.gov/earthquakes/eventpage/nc269151 | BE23: S&B | BF23: S&B::1992_capemendocino
A24: 1992_joshuatreeca | B24: Joshua Tree, CA | C24: 6.1 | D24: Original NGA source preferred | E24: 1992-04-23 | F24: 04:50:23.230Z | G24: USGS catalog timestamp | H24: 6.1 | I24: Mw | J24: 33.96 | K24: -116.3167 | L24: 12.4 | M24: Strike slip | N24: NGA-West2 representative fault plane | O24: 340 | P24: 90 | Q24: 180 | U24: Original NGA-West2 event metadata (coordinates, depth, magnitude); UTC time independently audited | V24: Original NGA-West2 strike/dip/rake | W24: ci3019681 | X24: https://peer.berkeley.edu/node/74 | Y24: Updated NGA-West2 RotD50 d050 public flatfile; row 6875; EQID 0146 | Z24: 1 | AB24: 340 | AC24: 90 | AD24: 180 | AE24: 5 | AF24: 8 | AG24: 10.5 | AH24: No matching USGS product in queried archive | AI24: Original NGA source parameters restored for S&B distances. USGS identity/time and finite-fault products are separate. Flatfile mirror provenance: Sources_method E03/E04. | AJ24: 2026-09-10 | BC24: NGA event name/year and EQID; USGS date, magnitude and location; sequence distinguished by origin time. | BD24: https://earthquake.usgs.gov/earthquakes/eventpage/ci3019681 | BE24: S&B | BF24: S&B::1992_joshuatreeca
A25: 1992_landers | B25: Landers | LANDERS | 1992_Landers_USA | C25: 7.3 | D25: Original NGA source preferred | E25: 1992-06-28 | F25: 11:57:34.130Z | G25: USGS catalog timestamp | H25: 7.28 | I25: Mw | J25: 34.2 | K25: -116.436 | L25: 7 | M25: Strike slip | N25: NGA-West2 representative fault plane | O25: 336 | P25: 90 | Q25: 180 | U25: Original NGA-West2 event metadata (coordinates, depth, magnitude); UTC time independently audited | V25: Original NGA-West2 strike/dip/rake | W25: ci3031111 | X25: https://peer.berkeley.edu/node/74 | Y25: Updated NGA-West2 RotD50 d050 public flatfile; row 833; EQID 0125 | Z25: 1 | AA25: Landers fault (S. Johnson Valley) | AB25: 336 | AC25: 90 | AD25: 180 | AE25: 0 | AF25: 71.8 | AG25: 15 | AH25: No matching USGS product in queried archive | AI25: Original NGA source parameters restored for S&B distances. USGS identity/time and finite-fault products are separate. Flatfile mirror provenance: Sources_method E03/E04. | AJ25: 2026-09-10 | BC25: NGA event name/year and EQID; USGS date, magnitude and location; sequence distinguished by origin time. | BD25: https://earthquake.usgs.gov/earthquakes/eventpage/ci3031111 | BE25: S&B | BF25: S&B::1992_landers
A26: 1994_northridge1 | B26: Northridge-01 | 1994_Northridge_01_USA | C26: 6.7 | D26: Original NGA source preferred | E26: 1994-01-17 | F26: 12:30:55.390Z | G26: USGS catalog timestamp | H26: 6.69 | I26: Mw | J26: 34.2057 | K26: -118.5539 | L26: 17.5 | M26: Reverse-oblique | N26: NGA-West2 representative fault plane | O26: 122 | P26: 40 | Q26: 103 | U26: Original NGA-West2 event metadata (coordinates, depth, magnitude); UTC time independently audited | V26: Original NGA-West2 strike/dip/rake | W26: ci3144585 | X26: https://peer.berkeley.edu/node/74 | Y26: Updated NGA-West2 RotD50 d050 public flatfile; row 943; EQID 0127 | Z26: 1 | AA26: Northridge Blind Thrust | AB26: 122 | AC26: 40 | AD26: 103 | AE26: 5 | AF26: 18 | AG26: 24 | AH26: No matching USGS product in queried archive | AI26: Original NGA source parameters restored for S&B distances. USGS identity/time and finite-fault products are separate. Flatfile mirror provenance: Sources_method E03/E04. | AJ26: 2026-09-10 | BC26: NGA event name/year and EQID; USGS date, magnitude and location; sequence distinguished by origin time. | BD26: https://earthquake.usgs.gov/earthquakes/eventpage/ci3144585 | BE26: S&B | BF26: S&B::1994_northridge1
A27: 1995_kobe | B27: Kobe, Japan | 1995_Kobe_Japan | C27: 6.9 | D27: Original NGA source preferred | E27: 1995-01-16 | F27: 20:46:52.120Z | G27: USGS catalog timestamp | H27: 6.9 | I27: Mw | J27: 34.596 | K27: 135.011 | L27: 17.9 | M27: Strike slip | N27: NGA-West2 representative fault plane | O27: 230 | P27: 85 | Q27: 180 | U27: Original NGA-West2 event metadata (coordinates, depth, magnitude); UTC time independently audited | V27: Original NGA-West2 strike/dip/rake | W27: usp0006rew | X27: https://peer.berkeley.edu/node/74 | Y27: Updated NGA-West2 RotD50 d050 public flatfile; row 1101; EQID 0129 | Z27: 1 | AB27: 230 | AC27: 85 | AD27: 180 | AE27: 0.2 | AF27: 60 | AG27: 20 | AH27: No matching USGS product in queried archive | AI27: Original NGA source parameters restored for S&B distances. USGS identity/time and finite-fault products are separate. Flatfile mirror provenance: Sources_method E03/E04. | AJ27: 2026-09-10 | BC27: NGA event name/year and EQID; USGS date, magnitude and location; sequence distinguished by origin time. | BD27: https://earthquake.usgs.gov/earthquakes/eventpage/usp0006rew | BE27: S&B | BF27: S&B::1995_kobe
A28: 1997_northwest3 | B28: Northwest China-03 | C28: 6.1 | D28: Original NGA source preferred | E28: 1997-04-11 | F28: 05:34:42.780Z | G28: USGS catalog timestamp | H28: 6.1 | I28: Mw | J28: 39.5557 | K28: 76.9477 | L28: 20 | M28: Normal | N28: NGA-West2 representative fault plane | O28: 21 | P28: 45 | Q28: -89 | U28: Original NGA-West2 event metadata (coordinates, depth, magnitude); UTC time independently audited | V28: Original NGA-West2 strike/dip/rake | W28: usp00080b7 | X28: https://peer.berkeley.edu/node/74 | Y28: Updated NGA-West2 RotD50 d050 public flatfile; row 1753; EQID 0155 | Z28: 0 | AB28: 21 | AC28: 45 | AD28: -89 | AE28: 14.648 | AF28: 14.4 | AG28: 11.8 | AH28: No matching USGS product in queried archive | AI28: Original NGA source parameters restored for S&B distances. USGS identity/time and finite-fault products are separate. Flatfile mirror provenance: Sources_method E03/E04. | AJ28: 2026-09-10 | BC28: NGA event name/year and EQID; USGS date, magnitude and location; sequence distinguished by origin time. | BD28: https://earthquake.usgs.gov/earthquakes/eventpage/usp00080b7 | BE28: S&B | BF28: S&B::1997_northwest3
A29: 1999_chichi | B29: Chi-Chi, Taiwan | CHICHI | 1999_ChiChi_Taiwan | C29: 7.6 | 7.65 | D29: Original NGA source preferred | E29: 1999-09-20 | F29: 17:47:18.490Z | G29: USGS catalog timestamp | H29: 7.62 | I29: Mw | J29: 23.85 | K29: 120.82 | L29: 8 | M29: Reverse-oblique | N29: NGA-West2 representative fault plane | O29: 20 | P29: 33 | Q29: 55 | U29: Original NGA-West2 event metadata (coordinates, depth, magnitude); UTC time independently audited | V29: Original NGA-West2 strike/dip/rake | W29: usp0009eq0 | X29: https://peer.berkeley.edu/node/74 | Y29: Updated NGA-West2 RotD50 d050 public flatfile; row 1179; EQID 0137 | Z29: 1 | AB29: 20 | AC29: 33 | AD29: 55 | AE29: 0 | AF29: 88 | AG29: 34.6 | AH29: USGS model matched | AI29: Original NGA source parameters restored for S&B distances. USGS identity/time and finite-fault products are separate. Flatfile mirror provenance: Sources_method E03/E04. | AJ29: 2026-09-10 | AK29: 1 | AL29: 7.58 | AM29: 3.0437142e+20 | AN29: 5.6365 | AO29: 7322.4 | AP29: 2.92 | AQ29: 1.32 | AR29: 23.834 | AS29: 120.813 | AT29: 10 | AU29: us | AV29: usp0009eq0 | AX29: 43390.383 | AY29: https://earthquake.usgs.gov/earthquakes/eventpage/usp0009eq0/finite-fault | AZ29: https://earthquake.usgs.gov/product/finite-fault/usp0009eq0/us/1539796251799/complete_inversion.fsp | BA29: https://earthquake.usgs.gov/product/finite-fault/usp0009eq0/us/1539796251799/basic_inversion.param | BB29: https://earthquake.usgs.gov/product/finite-fault/usp0009eq0/us/1539796251799/moment_rate.mr | BC29: NGA event name/year and EQID; USGS date, magnitude and location; sequence distinguished by origin time. | BD29: https://earthquake.usgs.gov/earthquakes/eventpage/usp0009eq0 | BE29: S&B | BF29: S&B::1999_chichi
A30: 1999_chichi3 | B30: Chi-Chi, Taiwan-03 | 1999_ChiChi_03_Taiwan | C30: 6.2 | 6.3 | D30: Original NGA source preferred | E30: 1999-09-20 | F30: 18:03:44.290Z | G30: USGS catalog timestamp | H30: 6.2 | I30: Mw | J30: 23.81 | K30: 120.85 | L30: 7.8 | M30: Reverse-oblique | N30: NGA-West2 representative fault plane | O30: 360 | P30: 10 | Q30: 80 | U30: Original NGA-West2 event metadata (coordinates, depth, magnitude); UTC time independently audited | V30: Original NGA-West2 strike/dip/rake | W30: usp0009eq5 | X30: https://peer.berkeley.edu/node/74 | Y30: Updated NGA-West2 RotD50 d050 public flatfile; row 2453; EQID 0172 | Z30: 1 | AB30: 360 | AC30: 10 | AD30: 80 | AE30: 6.7 | AF30: 10 | AG30: 11 | AH30: No matching USGS product in queried archive | AI30: Original NGA source parameters restored for S&B distances. USGS identity/time and finite-fault products are separate. Flatfile mirror provenance: Sources_method E03/E04. | AJ30: 2026-09-10 | BC30: NGA event name/year and EQID; USGS date, magnitude and location; sequence distinguished by origin time. | BD30: https://earthquake.usgs.gov/earthquakes/eventpage/usp0009eq5 | BE30: S&B | BF30: S&B::1999_chichi3
A31: 1999_chichi6 | B31: Chi-Chi, Taiwan-06 | 1999_ChiChi_07_Taiwan | C31: 6.3 | 6.49 | D31: Original NGA source preferred | E31: 1999-09-25 | F31: 23:52:48.660Z | G31: USGS catalog timestamp | H31: 6.3 | I31: Mw | J31: 23.87 | K31: 121.01 | L31: 16 | M31: Reverse-oblique | N31: NGA-West2 representative fault plane | O31: 5 | P31: 30 | Q31: 100 | U31: Original NGA-West2 event metadata (coordinates, depth, magnitude); UTC time independently audited | V31: Original NGA-West2 strike/dip/rake | W31: usp0009f1e | X31: https://peer.berkeley.edu/node/74 | Y31: Updated NGA-West2 RotD50 d050 public flatfile; row 3259; EQID 0175 | Z31: 1 | AB31: 5 | AC31: 30 | AD31: 100 | AE31: 10 | AF31: 29 | AG31: 20 | AH31: No matching USGS product in queried archive | AI31: Original NGA source parameters restored for S&B distances. USGS identity/time and finite-fault products are separate. Flatfile mirror provenance: Sources_method E03/E04. | AJ31: 2026-09-10 | BC31: NGA event name/year and EQID; USGS date, magnitude and location; sequence distinguished by origin time. Cross-sheet aliases inferred from identical original hypocenters and sequence table (Wang et al. 2004); workbook names differ. | BD31: https://earthquake.usgs.gov/earthquakes/eventpage/usp0009f1e | BE31: S&B | BF31: S&B::1999_chichi6
A32: 1999_chichi4 | B32: Chi-Chi, Taiwan-04 | 1999_Chiayi_Taiwan | C32: 6.2 | 6.42 | D32: Original NGA source preferred | E32: 1999-09-20 | F32: 21:46:42.870Z | G32: USGS catalog timestamp | H32: 6.2 | I32: Mw | J32: 23.6 | K32: 120.82 | L32: 18 | M32: Strike slip | N32: NGA-West2 representative fault plane | O32: 330 | P32: 89 | Q32: 15 | U32: Original NGA-West2 event metadata (coordinates, depth, magnitude); UTC time independently audited | V32: Original NGA-West2 strike/dip/rake | W32: usp0009erf | X32: https://peer.berkeley.edu/node/74 | Y32: Updated NGA-West2 RotD50 d050 public flatfile; row 2695; EQID 0173 | Z32: 1 | AB32: 330 | AC32: 89 | AD32: 15 | AE32: 1.5 | AF32: 21.5 | AG32: 17.5 | AH32: No matching USGS product in queried archive | AI32: Original NGA source parameters restored for S&B distances. USGS identity/time and finite-fault products are separate. Flatfile mirror provenance: Sources_method E03/E04. | AJ32: 2026-09-10 | BC32: NGA event name/year and EQID; USGS date, magnitude and location; sequence distinguished by origin time. Cross-sheet aliases inferred from identical original hypocenters and sequence table (Wang et al. 2004); workbook names differ. | BD32: https://earthquake.usgs.gov/earthquakes/eventpage/usp0009erf | BE32: S&B | BF32: S&B::1999_chichi4
A33: 1999_duzce | B33: Duzce, Turkey | DUZCE | 1999_Duzce_Turkey | C33: 7.1 | D33: Original NGA source preferred | E33: 1999-11-12 | F33: 16:57:19.550Z | G33: USGS catalog timestamp | H33: 7.14 | I33: Mw | J33: 40.8345 | K33: 31.1346 | L33: 14 | M33: Strike slip | N33: NGA-West2 representative fault plane | O33: 270 | P33: 65 | Q33: -178 | U33: Original NGA-West2 event metadata (coordinates, depth, magnitude); UTC time independently audited | V33: Original NGA-West2 strike/dip/rake | W33: usp0009hev | X33: https://peer.berkeley.edu/node/74 | Y33: Updated NGA-West2 RotD50 d050 public flatfile; row 1600; EQID 0138 | Z33: 1 | AB33: 270 | AC33: 65 | AD33: -178 | AE33: 0 | AF33: 46.8 | AG33: 20 | AH33: No matching USGS product in queried archive | AI33: Original NGA source parameters restored for S&B distances. USGS identity/time and finite-fault products are separate. Flatfile mirror provenance: Sources_method E03/E04. | AJ33: 2026-09-10 | BC33: NGA event name/year and EQID; USGS date, magnitude and location; sequence distinguished by origin time. | BD33: https://earthquake.usgs.gov/earthquakes/eventpage/usp0009hev | BE33: S&B | BF33: S&B::1999_duzce
